Workbook

Sheet README
A1: Lesson Map — AC9 Mathematics 7-10
A3: Purpose
A4: Single source of truth for the planned interactive HTML lesson library. One row per planned lesson on the 'Lessons' sheet. Each lesson is tagged to AC9 descriptor(s) and elaboration(s), so the spreadsheet doubles as a curriculum-coverage audit trail. Tasks.txt files for overnight batches are generated FROM this sheet — pick a slice of unbuilt rows, transform to task prompts, run the batch.
A6: Sheet structure
A7: Lessons | B7: Primary working sheet. One row per planned lesson. Add/edit here as the library is planned.
A8: Descriptors | B8: Reference. The 101 AC9 v9 Mathematics content descriptors for Years 7-10. Read-only.
A9: SA Mapping | B9: Reference. SA Conceptual Understandings → AC9 descriptor codes. To be populated from the SA Curriculum Prototype PDF.
A10: Coverage Report | B10: Auto-generated summary: descriptors covered, lessons built, lessons published, gaps.
A12: Column conventions (Lessons sheet)
A13: Lesson ID | B13: Stable identifier, e.g. y7_num_01. Used to derive filename.
A14: Year | B14: SA Year level where this lesson is taught (7-10).
A15: Strand | B15: Number / Algebra / Measurement / Space / Statistics / Probability.
A16: Lesson # | B16: Sequence within Year+Strand. Two-digit (01-99).
A17: Topic (snake_case) | B17: Used in filename. E.g. perfect_squares_and_roots.
A18: Filename | B18: Auto-built: y{Year}_{strand_abbr}_{##}_{topic}_v2.html.
A19: AC9 Descriptor(s) | B19: Comma-separated AC9 codes. Most lessons are one code; some span multiple.
A20: Elaboration #s | B20: Which elaborations of that descriptor are covered. e.g. '1,3' or 'all'.
A21: Mapping note | B21: 'Strict' or 'Implied' or explanatory note for non-obvious mappings.
A22: SA Conceptual Understanding | B22: AUTHORITATIVE per SA_CIMT_Curriculum_Mapping_v5 / sa-curriculum-cu-mapping.json. The CU statement this lesson sits under at the SA Year level. Pre-populated; do not invent.
A23: Lesson focus | B23: One-line statement of what this lesson teaches.
A24: Practice style | B24: auto-marked / strategy-MCQ / matching / mixed. Hints at skill template needed.
... A29: Notes | B29: Free-text: cohort considerations, watershed flags, re-generation history.
A31: Workflow
A32: 1. Plan: in Claude.ai project chat, work through one Year+Strand at a time. Decide lesson splits. Output rows to add here.
A33: 2. Add rows to Lessons sheet (Status = Planned). Pre-populate SA Conceptual Understanding from sa-curriculum-cu-mapping.json.
A34: 3. Pick a batch: filter Lessons by Status=Planned for the next overnight run (~10 lessons).
A35: 4. Generate tasks.txt: ask Claude.ai to transform those rows into tasks.txt entries using the standard task pattern. CU column copies straight through — no lookup needed.
A36: 5. Run overnight batch on Dell. Update Status to Generated + Generated date.
A37: 6. Review lessons. Update Status to Reviewed (or back to Planned with a Note if regenerating).
A38: 7. Publish. Update Status to Published + Published URL.
A39: 8. Coverage Report sheet auto-summarises progress.

Sheet Lessons
A1: Lesson ID | B1: Year | C1: Strand | D1: Lesson # | E1: Topic (snake_case) | F1: Filename | G1: AC9 Descriptor(s) | H1: Elaboration #s | I1: Mapping note | J1: SA Conceptual Understanding | K1: Lesson focus | L1: Practice style | M1: Prerequisites | N1: Status | O1: Generated date | P1: Published URL | Q1: Notes
A2: y7_num_01 | B2: 7 | C2: Number | D2: 01 | E2: perfect_squares_and_roots | F2: ="y"&B2&"_"&IF(C2="Number","num",IF(C2="Algebra","alg",IF(C2="Measurement","meas",IF(C2="Space","space",IF(C2="Statistics","stats",IF(C2="Probability","prob","UNK"))))))&"_"&D2&"_"&E2&"_v2.html" | G2: AC9M7N01 | H2: 1,3,4 | I2: Strict | J2: Rational numbers can be represented in many equivalent ways | K2: Build perfect squares from dot/area visuals; relate squares and roots as inverse; estimate √n between consecutive integers; spot patterns. | L2: auto-marked | N2: Published | P2: https://seager94.github.io/year-7/number/y7_num_01_perfect_squares_and_roots_v2.html | Q2: Status reconciled from repo 2026-05-30 (generated date unconfirmed)
A3: y7_num_02 | B3: 7 | C3: Number | D3: 02 | E3: squaring_and_problem_solving | F3: ="y"&B3&"_"&IF(C3="Number","num",IF(C3="Algebra","alg",IF(C3="Measurement","meas",IF(C3="Space","space",IF(C3="Statistics","stats",IF(C3="Probability","prob","UNK"))))))&"_"&D3&"_"&E3&"_v2.html" | G3: AC9M7N01 | H3: 2,5 | I3: Strict | J3: Rational numbers can be represented in many equivalent ways | K3: Square two-digit numbers via (40+3)²; apply to tiled-floor area/perimeter problems. | L3: auto-marked | M3: y7_num_01 | N3: Published | P3: https://seager94.github.io/year-7/number/y7_num_02_squaring_and_problem_solving_v2.html | Q3: Status reconciled from repo 2026-05-30 (generated date unconfirmed)
A4: y7_num_03 | B4: 7 | C4: Number | D4: 03 | E4: prime_factorisation | F4: ="y"&B4&"_"&IF(C4="Number","num",IF(C4="Algebra","alg",IF(C4="Measurement","meas",IF(C4="Space","space",IF(C4="Statistics","stats",IF(C4="Probability","prob","UNK"))))))&"_"&D4&"_"&E4&"_v2.html" | G4: AC9M7N02 | H4: 1,2 | I4: Strict | J4: Numbers with repeated factors can be expressed using exponential notation | K4: Factor trees and repeated prime division; express n as products of prime powers; build fluency with powers of 2, 3, 5. | L4: auto-marked | N4: Published | P4: https://seager94.github.io/year-7/number/y7_num_03_prime_factorisation_v2.html | Q4: Status reconciled from repo 2026-05-30 (generated date unconfirmed)
A5: y7_num_04 | B5: 7 | C5: Number | D5: 04 | E5: lcm_hcf_via_prime_factors | F5: ="y"&B5&"_"&IF(C5="Number","num",IF(C5="Algebra","alg",IF(C5="Measurement","meas",IF(C5="Space","space",IF(C5="Statistics","stats",IF(C5="Probability","prob","UNK"))))))&"_"&D5&"_"&E5&"_v2.html" | G5: AC9M7N02 | H5: 3 | I5: Strict | J5: Numbers with repeated factors can be expressed using exponential notation | K5: Find LCM and HCF by comparing prime factorisations. Timetable/packaging contexts. | L5: auto-marked | M5: y7_num_03 | N5: Published | P5: https://seager94.github.io/year-7/number/y7_num_04_lcm_hcf_via_prime_factors_v2.html | Q5: Status reconciled from repo 2026-05-30 (generated date unconfirmed)
A6: y7_num_05 | B6: 7 | C6: Number | D6: 05 | E6: expanded_notation_powers_of_10 | F6: ="y"&B6&"_"&IF(C6="Number","num",IF(C6="Algebra","alg",IF(C6="Measurement","meas",IF(C6="Space","space",IF(C6="Statistics","stats",IF(C6="Probability","prob","UNK"))))))&"_"&D6&"_"&E6&"_v2.html" | G6: AC9M7N03 | H6: all | I6: Strict | J6: Rational numbers can be represented in many equivalent ways | K6: Powers of 10 notation; sequence 10, 100, 1000 ↔ 10¹, 10², 10³; expanded notation using place value. | L6: auto-marked | N6: Published | P6: https://seager94.github.io/year-7/number/y7_num_05_expanded_notation_powers_of_10_v2.html | Q6: Status reconciled from repo 2026-05-30 (generated date unconfirmed)
A7: y7_num_06 | B7: 7 | C7: Number | D7: 06 | E7: equivalent_fractions | F7: ="y"&B7&"_"&IF(C7="Number","num",IF(C7="Algebra","alg",IF(C7="Measurement","meas",IF(C7="Space","space",IF(C7="Statistics","stats",IF(C7="Probability","prob","UNK"))))))&"_"&D7&"_"&E7&"_v2.html" | G7: AC9M7N04 | H7: 1,2 | I7: Strict | J7: Rational numbers can be represented in many equivalent ways | K7: Equivalent fractions via common multiples, fraction wall, number line; simplify using common divisors. | L7: auto-marked | N7: Published | P7: https://seager94.github.io/year-7/number/y7_num_06_equivalent_fractions_v2.html | Q7: Status reconciled from repo 2026-05-30 (generated date unconfirmed)
A8: y7_num_07 | B8: 7 | C8: Number | D8: 07 | E8: fractions_decimals_percentages | F8: ="y"&B8&"_"&IF(C8="Number","num",IF(C8="Algebra","alg",IF(C8="Measurement","meas",IF(C8="Space","space",IF(C8="Statistics","stats",IF(C8="Probability","prob","UNK"))))))&"_"&D8&"_"&E8&"_v2.html" | G8: AC9M7N04 | H8: 3 | I8: Strict | J8: Rational numbers can be represented in many equivalent ways | K8: Convert between fraction, decimal, percentage. Benchmark equivalences (¼, ½, ¾, ⅛, tenths). | L8: auto-marked | M8: y7_num_06 | N8: Published | P8: https://seager94.github.io/year-7/number/y7_num_07_fractions_decimals_percentages_v2.html | Q8: Status reconciled from repo 2026-05-30 (generated date unconfirmed)
A9: y7_num_08 | B9: 7 | C9: Number | D9: 08 | E9: rationals_on_number_line | F9: ="y"&B9&"_"&IF(C9="Number","num",IF(C9="Algebra","alg",IF(C9="Measurement","meas",IF(C9="Space","space",IF(C9="Statistics","stats",IF(C9="Probability","prob","UNK"))))))&"_"&D9&"_"&E9&"_v2.html" | G9: AC9M7N04 | H9: 4 | I9: Strict | J9: Rational numbers can be represented in many equivalent ways | K9: Locate positive and negative fractions/mixed numerals on number line, including asymmetric intervals. | L9: auto-marked | M9: y7_num_06 | N9: Published | P9: https://seager94.github.io/year-7/number/y7_num_08_rationals_on_number_line_v2.html | Q9: Status reconciled from repo 2026-05-30 (generated date unconfirmed)
A10: y7_num_09 | B10: 7 | C10: Number | D10: 09 | E10: rounding_and_reasonableness | F10: ="y"&B10&"_"&IF(C10="Number","num",IF(C10="Algebra","alg",IF(C10="Measurement","meas",IF(C10="Space","space",IF(C10="Statistics","stats",IF(C10="Probability","prob","UNK"))))))&"_"&D10&"_"&E10&"_v2.html" | G10: AC9M7N05 | H10: all | I10: Strict | J10: Rational numbers can be approximated to support judgements of magnitude and reasonableness | K10: Round decimals to specified accuracy; check reasonableness via estimation. Finance/renovation contexts. | L10: auto-marked | N10: Published | P10: https://seager94.github.io/year-7/number/y7_num_09_rounding_and_reasonableness_v2.html | Q10: Status reconciled from repo 2026-05-30 (generated date unconfirmed)
A11: y7_num_10 | B11: 7 | C11: Number | D11: 10 | E11: adding_subtracting_fractions | F11: ="y"&B11&"_"&IF(C11="Number","num",IF(C11="Algebra","alg",IF(C11="Measurement","meas",IF(C11="Space","space",IF(C11="Statistics","stats",IF(C11="Probability","prob","UNK"))))))&"_"&D11&"_"&E11&"_v2.html" | G11: AC9M7N06 | H11: 1,5 | I11: Strict | J11: The inverse relationships between addition and subtraction and multiplication and division can be used to add, subtract, multiply or divide rational numbers | K11: Add and subtract fractions and decimals using rectangular arrays, algebra tiles, partitioning. | L11: auto-marked | M11: y7_num_06 | N11: Published | P11: https://seager94.github.io/year-7/number/y7_num_10_adding_subtracting_fractions_v2.html | Q11: Status reconciled from repo 2026-05-30 (generated date unconfirmed)
A12: y7_num_11 | B12: 7 | C12: Number | D12: 11 | E12: multiplying_dividing_fractions | F12: ="y"&B12&"_"&IF(C12="Number","num",IF(C12="Algebra","alg",IF(C12="Measurement","meas",IF(C12="Space","space",IF(C12="Statistics","stats",IF(C12="Probability","prob","UNK"))))))&"_"&D12&"_"&E12&"_v2.html" | G12: AC9M7N06 | H12: 3,4 | I12: Strict | J12: Multiplying a positive number by a number greater than 0 and less than 1 results in a smaller number | K12: Multiply and divide fractions and decimals. Conceptual models first (fraction walls, arrays), then procedure. | L12: auto-marked | M12: y7_num_06 | N12: Published | P12: https://seager94.github.io/year-7/number/y7_num_11_multiplying_dividing_fractions_v2.html | Q12: Status reconciled from repo 2026-05-30 (generated date unconfirmed)
A13: y7_num_12 | B13: 7 | C13: Number | D13: 12 | E13: choosing_efficient_representations | F13: ="y"&B13&"_"&IF(C13="Number","num",IF(C13="Algebra","alg",IF(C13="Measurement","meas",IF(C13="Space","space",IF(C13="Statistics","stats",IF(C13="Probability","prob","UNK"))))))&"_"&D13&"_"&E13&"_v2.html" | G13: AC9M7N06 | H13: 2,6 | I13: Strict | J13: The inverse relationships between addition and subtraction and multiplication and division can be used to add, subtract, multiply or divide rational numbers | K13: Strategic choice between fraction, decimal, percentage forms for efficient calculation (e.g. 12.5% × 96 as ⅛ × 96). | L13: Option B: calc lesson with strategic I Do | M13: y7_num_07,y7_num_10,y7_num_11 | N13: Published | P13: https://seager94.github.io/year-7/number/y7_num_12_choosing_efficient_representations_v2.html | Q13: Status reconciled from repo 2026-05-30 (generated date unconfirmed)
A14: y7_num_13 | B14: 7 | C14: Number | D14: 13 | E14: percentage_of_a_quantity | F14: ="y"&B14&"_"&IF(C14="Number","num",IF(C14="Algebra","alg",IF(C14="Measurement","meas",IF(C14="Space","space",IF(C14="Statistics","stats",IF(C14="Probability","prob","UNK"))))))&"_"&D14&"_"&E14&"_v2.html" | G14: AC9M7N06 | H14: — | I14: Implied | J14: The inverse relationships between addition and subtraction and multiplication and division can be used to add, subtract, multiply or divide rational numbers | K14: Find a percentage of a quantity (e.g. 15% of $80). Foundational for N09 modelling. | L14: auto-marked | M14: y7_num_07 | N14: Published | P14: https://seager94.github.io/year-7/number/y7_num_13_percentage_of_a_quantity_v2.html | Q14: Status reconciled from repo 2026-05-30 (generated date unconfirmed)
A15: y7_num_14 | B15: 7 | C15: Number | D15: 14 | E15: comparing_ordering_integers | F15: ="y"&B15&"_"&IF(C15="Number","num",IF(C15="Algebra","alg",IF(C15="Measurement","meas",IF(C15="Space","space",IF(C15="Statistics","stats",IF(C15="Probability","prob","UNK"))))))&"_"&D15&"_"&E15&"_v2.html" | G15: AC9M7N07 | H15: 1,2 | I15: Strict | J15: The inverse relationships between addition and subtraction and multiplication and division can be used to add, subtract, multiply or divide rational numbers | K15: < and > with positive/negative integers; language work (magnitude, difference, sign); ordering on number line. | L15: auto-marked | M15: y7_num_08 | N15: Published | P15: https://seager94.github.io/year-7/number/y7_num_14_comparing_ordering_integers_v2.html | Q15: Status reconciled from repo 2026-05-30 (generated date unconfirmed)
A16: y7_num_15 | B16: 7 | C16: Number | D16: 15 | E16: adding_subtracting_integers | F16: ="y"&B16&"_"&IF(C16="Number","num",IF(C16="Algebra","alg",IF(C16="Measurement","meas",IF(C16="Space","space",IF(C16="Statistics","stats",IF(C16="Probability","prob","UNK"))))))&"_"&D16&"_"&E16&"_v2.html" | G16: AC9M7N07, AC9M7N09 | H16: 3 (N07); 1 (N09) | I16: Strict + cross-tag | J16: The inverse relationships between addition and subtraction and multiplication and division can be used to add, subtract, multiply or divide rational numbers | K16: Add and subtract integers using number-line model; apply to lifts/altitude/sea-level modelling. | L16: auto-marked | M16: y7_num_14 | N16: Published | P16: https://seager94.github.io/year-7/number/y7_num_15_adding_subtracting_integers_v2.html | Q16: Status reconciled from repo 2026-05-30 (generated date unconfirmed)
A17: y7_num_16 | B17: 7 | C17: Number | D17: 16 | E17: representing_ratios | F17: ="y"&B17&"_"&IF(C17="Number","num",IF(C17="Algebra","alg",IF(C17="Measurement","meas",IF(C17="Space","space",IF(C17="Statistics","stats",IF(C17="Probability","prob","UNK"))))))&"_"&D17&"_"&E17&"_v2.html" | G17: AC9M7N08 | H17: 1,2 | I17: Strict | J17: Fractions, percentages, ratios and rates are different ways of representing a proportional relationship between quantities | K17: Ratios as quantitative comparison of groups; part-part vs part-whole; connection to fractions. | L17: auto-marked | M17: y7_num_06 | N17: Published | P17: https://seager94.github.io/year-7/number/y7_num_16_representing_ratios_v2.html | Q17: Status reconciled from repo 2026-05-30 (generated date unconfirmed)
A18: y7_num_17 | B18: 7 | C18: Number | D18: 17 | E18: sharing_in_a_ratio | F18: ="y"&B18&"_"&IF(C18="Number","num",IF(C18="Algebra","alg",IF(C18="Measurement","meas",IF(C18="Space","space",IF(C18="Statistics","stats",IF(C18="Probability","prob","UNK"))))))&"_"&D18&"_"&E18&"_v2.html" | G18: AC9M7N08 | H18: 3,4 | I18: Strict | J18: Fractions, percentages, ratios and rates are different ways of representing a proportional relationship between quantities | K18: Divide a quantity in a given ratio. Applied contexts: money, mixtures, concentrations. | L18: auto-marked | M18: y7_num_16 | N18: Published | P18: https://seager94.github.io/year-7/number/y7_num_17_sharing_in_a_ratio_v2.html | Q18: Status reconciled from repo 2026-05-30 (generated date unconfirmed)
A19: y7_num_18 | B19: 7 | C19: Number | D19: 18 | E19: modelling_with_proportion | F19: ="y"&B19&"_"&IF(C19="Number","num",IF(C19="Algebra","alg",IF(C19="Measurement","meas",IF(C19="Space","space",IF(C19="Statistics","stats",IF(C19="Probability","prob","UNK"))))))&"_"&D19&"_"&E19&"_v2.html" | G19: AC9M7N09 | H19: 2,4 | I19: Strict | J19: Mathematical modelling can be used to represent and analyse financial and other real-world situations and support informed decision-making | K19: Modelling proportional contexts: attendance, voting, land use. Includes First Nations grain-belt comparison. | L19: auto-marked + open-ended | M19: y7_num_13,y7_num_16 | N19: Published | P19: https://seager94.github.io/year-7/number/y7_num_18_modelling_with_proportion_v2.html | Q19: Status reconciled from repo 2026-05-30 (generated date unconfirmed)
A20: y7_num_19 | B20: 7 | C20: Number | D20: 19 | E20: modelling_profit_and_loss | F20: ="y"&B20&"_"&IF(C20="Number","num",IF(C20="Algebra","alg",IF(C20="Measurement","meas",IF(C20="Space","space",IF(C20="Statistics","stats",IF(C20="Probability","prob","UNK"))))))&"_"&D20&"_"&E20&"_v2.html" | G20: AC9M7N09 | H20: 3 | I20: Strict | J20: Mathematical modelling can be used to represent and analyse financial and other real-world situations and support informed decision-making | K20: Financial modelling: profit/loss/% profit on fundraiser scenarios. | L20: auto-marked + open-ended | M20: y7_num_13 | N20: Published | P20: https://seager94.github.io/year-7/number/y7_num_19_modelling_profit_and_loss_v2.html | Q20: Status reconciled from repo 2026-05-30 (generated date unconfirmed)
A21: y7_alg_01 | B21: 7 | C21: Algebra | D21: 01 | E21: variables_and_algebraic_notation | F21: y7_alg_01_variables_and_algebraic_notation_v2.html | G21: AC9M7A02 | H21: 1 | I21: Strict | J21: Algebraic expressions can be represented in infinitely many different but equivalent ways | K21: Introduce variable as a letter representing a number; notation conventions (3x = 3×x, no × symbol); distinguish 3x+4 from 3(x+4); generalise from arithmetic patterns like 7+7+7 = 3×7. | L21: auto-marked | N21: Published | O21: 2026-05-20 | P21: https://seager94.github.io/year-7/algebra/y7_alg_01_variables_and_algebraic_notation_v2.html | Q21: Watershed — foundation for the whole strand.
A22: y7_alg_02 | B22: 7 | C22: Algebra | D22: 02 | E22: translating_words_to_expressions | F22: y7_alg_02_translating_words_to_expressions_v2.html | G22: AC9M7A02 | H22: 2 | I22: Strict | J22: Algebraic expressions can be represented in infinitely many different but equivalent ways | K22: Translate worded statements into algebraic expressions; 'think of a number' puzzles; vocab work. | L22: auto-marked | M22: y7_alg_01 | N22: Published | O22: 2026-05-20 | P22: https://seager94.github.io/year-7/algebra/y7_alg_02_translating_words_to_expressions_v2.html | Q22: Misconception: '5 less than n' is n-5, not 5-n. Error Analysis block.
A23: y7_alg_03 | B23: 7 | C23: Algebra | D23: 03 | E23: substituting_into_expressions | F23: y7_alg_03_substituting_into_expressions_v2.html | G23: AC9M7A01 | H23: 3 (partial) | I23: Strict | J23: Patterns and relationships between variables can be described algebraically and graphed to solve problems and support inferences | K23: Evaluate single- and multi-variable expressions; emphasis on order of operations and negative substitutions. | L23: auto-marked | M23: y7_alg_01 | N23: Published | O23: 2026-05-20 | P23: https://seager94.github.io/year-7/algebra/y7_alg_03_substituting_into_expressions_v2.html | Q23: Order-of-ops: 3x² where x=4 gives 48, not 144.
A24: y7_alg_04 | B24: 7 | C24: Algebra | D24: 04 | E24: substituting_into_everyday_formulas | F24: y7_alg_04_substituting_into_everyday_formulas_v2.html | G24: AC9M7A01 | H24: 1, 2, 3 | I24: Strict | J24: Patterns and relationships between variables can be described algebraically and graphed to solve problems and support inferences | K24: Substitute into A=l×w, AFL p=6g+b, target heart rate, wages W=b+1.5hr, density d=m/v. | L24: auto-marked | M24: y7_alg_03 | N24: Published | O24: 2026-05-20 | P24: https://seager94.github.io/year-7/algebra/y7_alg_04_substituting_into_everyday_formulas_v2.html | Q24: Watershed. Wages-with-overtime and density carried as Stretch.
A25: y7_alg_05 | B25: 7 | C25: Algebra | D25: 05 | E25: collecting_like_terms | F25: y7_alg_05_collecting_like_terms_v2.html | G25: AC9M7A02 | H25: 1, 3 | I25: Strict | J25: The commutative and associative properties apply to addition and multiplication, but not to subtraction and division | K25: Identify like terms; combine using commutative/associative properties; algebra-tile visuals; distinguish x and x² as different objects. | L25: auto-marked | M25: y7_alg_01 | N25: Published | O25: 2026-05-20 | P25: https://seager94.github.io/year-7/algebra/y7_alg_05_collecting_like_terms_v2.html | Q25: Watershed. Misconception: 3x + 2 = 5x. Error Analysis.
A26: y7_alg_06 | B26: 7 | C26: Algebra | D26: 06 | E26: distributive_law_expanding_brackets | F26: y7_alg_06_distributive_law_expanding_brackets_v2.html | G26: AC9M7A02 | H26: 1, 3 | I26: Strict | J26: The distributive property of multiplication over addition and subtraction can be used to support efficient calculation | K26: Expand single brackets; area-model visualisation first; 3(x+4) = 3x+12; efficient arithmetic via 7×98 = 7(100−2). | L26: auto-marked | M26: y7_alg_05 | N26: Published | O26: 2026-05-20 | P26: https://seager94.github.io/year-7/algebra/y7_alg_06_distributive_law_expanding_brackets_v2.html | Q26: Watershed. Builds toward Y8 binomials.
A27: y7_alg_07 | B27: 7 | C27: Algebra | D27: 07 | E27: meaning_of_solving_an_equation | F27: y7_alg_07_meaning_of_solving_an_equation_v2.html | G27: AC9M7A03 | H27: 1 | I27: Strict | J27: Patterns and relationships between variables can be described algebraically and graphed to solve problems and support inferences | K27: Equation as truth statement; solving = finding the value that makes it true; verify candidate solutions by substitution. | L27: auto-marked | M27: y7_alg_03 | N27: Published | O27: 2026-05-20 | P27: https://seager94.github.io/year-7/algebra/y7_alg_07_meaning_of_solving_an_equation_v2.html | Q27: Practice is 'is x=4 a solution to…?' not 'solve for x'.
A28: y7_alg_08 | B28: 7 | C28: Algebra | D28: 08 | E28: solving_by_backtracking_and_balance | F28: y7_alg_08_solving_by_backtracking_and_balance_v2.html | G28: AC9M7A03 | H28: 2 | I28: Strict | J28: Patterns and relationships between variables can be described algebraically and graphed to solve problems and support inferences | K28: Function-machine backtracking and balance-scale models; step-by-step reasoning before going algebraic. | L28: auto-marked | M28: y7_alg_07 | N28: Published | O28: 2026-05-20 | P28: https://seager94.github.io/year-7/algebra/y7_alg_08_solving_by_backtracking_and_balance_v2.html | Q28: Concrete-pictorial before algebraic in L09.
A29: y7_alg_09 | B29: 7 | C29: Algebra | D29: 09 | E29: solving_linear_equations_algebraically | F29: y7_alg_09_solving_linear_equations_algebraically_v2.html | G29: AC9M7A03 | H29: 3 | I29: Strict | J29: Patterns and relationships between variables can be described algebraically and graphed to solve problems and support inferences | K29: Solve ax+b=c algebraically using inverse operations; verify every solution by substitution. | L29: auto-marked | M29: y7_alg_08 | N29: Published | O29: 2026-05-20 | P29: https://seager94.github.io/year-7/algebra/y7_alg_09_solving_linear_equations_algebraically_v2.html | Q29: Watershed — destination of the equations track. Verification step explicit.
A30: y7_alg_10 | B30: 7 | C30: Algebra | D30: 10 | E30: patterns_to_tables_of_values | F30: y7_alg_10_patterns_to_tables_of_values_v2.html | G30: AC9M7A05 | H30: 2, 4 | I30: Strict | J30: Patterns and relationships between variables can be described algebraically and graphed to solve problems and support inferences | K30: Build table from visually growing pattern; describe relationship; generalise to rule; use rule to find later terms. | L30: auto-marked | M30: y7_alg_01 | N30: Published | O30: 2026-05-21 | P30: https://seager94.github.io/year-7/algebra/y7_alg_10_patterns_to_tables_of_values_v2.html
A31: y7_alg_11 | B31: 7 | C31: Algebra | D31: 11 | E31: plotting_linear_relationships_on_cartesian_plane | F31: y7_alg_11_plotting_linear_relationships_on_cartesian_plane_v2.html | G31: AC9M7A05 | H31: 1, 3 | I31: Strict | J31: Patterns and relationships between variables can be described algebraically and graphed to solve problems and support inferences | K31: Plot ordered pairs from table on Cartesian plane; linear rules produce straight lines; function machines as input-output generators. | L31: auto-marked | M31: y7_alg_10 | N31: Published | O31: 2026-05-21 | P31: https://seager94.github.io/year-7/algebra/y7_alg_11_plotting_linear_relationships_on_cartesian_plane_v2.html | Q31: Watershed — first formal Cartesian plotting. Filename drifted from planned 'cartesian' to 'on_cartesian_plane'; published URL is source of truth.
A32: y7_alg_12 | B32: 7 | C32: Algebra | D32: 12 | E32: telling_stories_from_graphs | F32: y7_alg_12_telling_stories_from_graphs_v2.html | G32: AC9M7A04 | H32: 1, 2, 3, 4 | I32: Strict | J32: Patterns and relationships between variables can be described algebraically and graphed to solve problems and support inferences | K32: Interpret authentic-data graphs (temperature, electricity, travel, pouring rates); read values; identify features; match stories to shapes. | L32: auto-marked | M32: y7_alg_11 | N32: Published | O32: 2026-05-21 | P32: https://seager94.github.io/year-7/algebra/y7_alg_12_telling_stories_from_graphs_v2.html | Q32: Mastery: First Nations water-resource management evaporation graphs. Reflection questions are the only non-auto-marked elements.
A33: y7_alg_13 | B33: 7 | C33: Algebra | D33: 13 | E33: manipulating_formulas_systematic_variation | F33: y7_alg_13_manipulating_formulas_systematic_variation_v2.html | G33: AC9M7A06 | H33: 1, 2, 3 | I33: Strict | J33: Patterns and relationships between variables can be described algebraically and graphed to solve problems and support inferences | K33: Reactive tables to vary inputs in formulas (V=lwh, d=st); describe effect of systematic variation. | L33: auto-marked | M33: y7_alg_04 | N33: Published | O33: 2026-05-21 | P33: https://seager94.github.io/year-7/algebra/y7_alg_13_manipulating_formulas_systematic_variation_v2.html | Q33: HTML lesson uses embedded reactive tables as the 'digital tool'. Section 4 same-volume puzzle was a nice CC addition. Excel/Sheets follow-up recommended.
A34: y7_mea_01 | B34: 7 | C34: Measurement | D34: 1 | E34: area_of_triangles | F34: y7_mea_01_area_of_triangles_v2.html | G34: AC9M7M01 | H34: 1,2 | I34: Strict | J34: Measurable attributes of 2-dimensional shapes and 3-dimensional objects can be determined based on the known properties of the shape or solid | K34: Derive area of a triangle as half an appropriate rectangle (½×base×height); identify the perpendicular height (not just any side); calculate areas of acute, obtuse and right-angled triangles. | L34: auto-marked | M34: y7_num_10 | N34: Published | O34: 2026-05-21 | P34: https://seager94.github.io/year-7/measurement/y7_mea_01_area_of_triangles_v2.html | Q34: Cross-strand prereq: fraction arithmetic for the ½ multiplier.
A35: y7_mea_02 | B35: 7 | C35: Measurement | D35: 2 | E35: area_of_parallelograms | F35: y7_mea_02_area_of_parallelograms_v2.html | G35: AC9M7M01 | H35: 1,3 | I35: Strict | J35: Measurable attributes of 2-dimensional shapes and 3-dimensional objects can be determined based on the known properties of the shape or solid | K35: Derive A=base×height for parallelograms by re-arranging into a rectangle; identify the perpendicular height; shade-sail and tiling cost problems. | L35: auto-marked | M35: y7_mea_01 | N35: Published | O35: 2026-05-21 | P35: https://seager94.github.io/year-7/measurement/y7_mea_02_area_of_parallelograms_v2.html
A36: y7_mea_03 | B36: 7 | C36: Measurement | D36: 3 | E36: volume_of_rectangular_prisms | F36: y7_mea_03_volume_of_rectangular_prisms_v2.html | G36: AC9M7M02 | H36: 1,3 | I36: Strict | J36: Measurable attributes of 2-dimensional shapes and 3-dimensional objects can be determined based on the known properties of the shape or solid | K36: Build rectangular prisms from unit cubes; derive V=l×w×h; apply to high-rise volume (floor area × number of floors); convert between cm³, m³ and capacity (mL, L). | L36: auto-marked | N36: Published | O36: 2026-05-21 | P36: https://seager94.github.io/year-7/measurement/y7_mea_03_volume_of_rectangular_prisms_v2.html
A37: y7_mea_04 | B37: 7 | C37: Measurement | D37: 4 | E37: volume_of_triangular_prisms | F37: y7_mea_04_volume_of_triangular_prisms_v2.html | G37: AC9M7M02 | H37: 2,4 | I37: Strict | J37: Measurable attributes of 2-dimensional shapes and 3-dimensional objects can be determined based on the known properties of the shape or solid | K37: Generalise to V = cross-section area × length for any right prism; calculate volumes of triangular prisms; predict-and-test cross-section reasoning. | L37: auto-marked | M37: y7_mea_01,y7_mea_03 | N37: Published | O37: 2026-05-21 | P37: https://seager94.github.io/year-7/measurement/y7_mea_04_volume_of_triangular_prisms_v2.html
A38: y7_mea_05 | B38: 7 | C38: Measurement | D38: 5 | E38: features_of_circles | F38: y7_mea_05_features_of_circles_v2.html | G38: AC9M7M03 | H38: 1,4 | I38: Strict | J38: In any circle, the ratio of the circumference to the diameter is always the same and is represented by the number pi (π) | K38: Identify and label centre, radius, diameter, chord and circumference; use the relationship d=2r; First Nations Australians' use of circles in basketry, symbols and architecture. | L38: auto-marked | N38: Published | O38: 2026-05-21 | P38: https://seager94.github.io/year-7/measurement/y7_mea_05_features_of_circles_v2.html
A39: y7_mea_06 | B39: 7 | C39: Measurement | D39: 6 | E39: introducing_pi | F39: y7_mea_06_introducing_pi_v2.html | G39: AC9M7M03 | H39: 2,3 | I39: Strict | J39: In any circle, the ratio of the circumference to the diameter is always the same and is represented by the number pi (π) | K39: Measure circumference and diameter of round objects with string; record C÷d; observe the constant ratio ≈ π; historical approximations of π from Egypt, Babylon, Greece, India and China. | L39: auto-marked + open-ended | M39: y7_mea_05 | N39: Published | O39: 2026-05-21 | P39: https://seager94.github.io/year-7/measurement/y7_mea_06_introducing_pi_v2.html | Q39: Investigation lesson — practice should include some measurement-and-record task.
A40: y7_mea_07 | B40: 7 | C40: Measurement | D40: 7 | E40: parallel_lines_and_transversals | F40: y7_mea_07_parallel_lines_and_transversals_v2.html | G40: AC9M7M04 | H40: 1,2 | I40: Strict | J40: Parallel and intersecting lines have properties that can be used to deduce relationships between the angles formed | K40: Construct parallel lines; identify corresponding, alternate and co-interior angles when a transversal crosses parallel lines; calculate unknown angles using these relationships. | L40: auto-marked | N40: Published | O40: 2026-05-21 | P40: https://seager94.github.io/year-7/measurement/y7_mea_07_parallel_lines_and_transversals_v2.html
...

Sheet Descriptors
A1: Code | B1: Year | C1: Strand | D1: Descriptor | E1: Elaboration # | F1: Elaboration text
A2: AC9M7N01 | B2: 7 | C2: Number | D2: describe the relationship between perfect square numbers and square roots, and use squares of numbers and square roots of perfect square numbers to solve problems | E2: 1 | F2: investigating squares of natural numbers from one to 20, and connecting them to visual representations such as dots arranged in a square pattern
A3: AC9M7N01 | B3: 7 | C3: Number | D3: describe the relationship between perfect square numbers and square roots, and use squares of numbers and square roots of perfect square numbers to solve problems | E3: 2 | F3: using the square and square root notation, and the distributive property and area diagrams to calculate the squares of two-digit numbers; for example, 43²=(40+3)²=40²+2×40×3+3²=1600+240+9=1849
A4: AC9M7N01 | B4: 7 | C4: Number | D4: describe the relationship between perfect square numbers and square roots, and use squares of numbers and square roots of perfect square numbers to solve problems | E4: 3 | F4: determining between which 2 consecutive natural numbers the square root of a given number lies; for example, 43 is between the square numbers 36 and 49 so √(43) is between √(36) and √(49) and therefore between 6 and 7
A5: AC9M7N01 | B5: 7 | C5: Number | D5: describe the relationship between perfect square numbers and square roots, and use squares of numbers and square roots of perfect square numbers to solve problems | E5: 4 | F5: generating a list of perfect square numbers and describing any emerging patterns; for example, the last digit of perfect square numbers, or the difference between consecutive square numbers, and recognising the constant second difference
A6: AC9M7N01 | B6: 7 | C6: Number | D6: describe the relationship between perfect square numbers and square roots, and use squares of numbers and square roots of perfect square numbers to solve problems | E6: 5 | F6: using the relationship between perfect square numbers and their square roots to determine the perimeter of a square tiled floor using square tiles; for example, an area of floor with 144 square tiles has a perimeter of 48 tile lengths
A7: AC9M7N02 | B7: 7 | C7: Number | D7: represent natural numbers as products of powers of prime numbers using exponent notation | E7: 1 | F7: applying knowledge of factors to strategies for expressing natural numbers as products of powers of prime factors, such as repeated division by prime factors or creating factor trees; for example, 48=6×8=2×3×2×2×2=3¹×2⁴=3×2⁴
A8: AC9M7N02 | B8: 7 | C8: Number | D8: represent natural numbers as products of powers of prime numbers using exponent notation | E8: 2 | F8: developing familiarity with the sequence 1, 2, 4, 8, 16, 32, 64, 128, 256, 512 and powers of 2; the sequence 1, 3, 9, 27, 81, 243, 729 and powers of 3; and the sequence 1, 5, 25, 125, 625 and powers of 5
A9: AC9M7N02 | B9: 7 | C9: Number | D9: represent natural numbers as products of powers of prime numbers using exponent notation | E9: 3 | F9: solving problems involving lowest common multiples and greatest common divisors (highest common factors) for pairs of natural numbers by comparing their prime factorisation
A10: AC9M7N03 | B10: 7 | C10: Number | D10: represent natural numbers in expanded notation using place value and powers of 10 | E10: 1 | F10: investigating exponent notation for powers of 10 such as “one hundred thousand” is 100 000=10×10×10×10×10=10⁵
A11: AC9M7N03 | B11: 7 | C11: Number | D11: represent natural numbers in expanded notation using place value and powers of 10 | E11: 2 | F11: relating the sequences 10, 100, 1000, 10 000 … and 101, 102, 103, 104 ...
A12: AC9M7N03 | B12: 7 | C12: Number | D12: represent natural numbers in expanded notation using place value and powers of 10 | E12: 3 | F12: applying and explaining the connections between place value and expanded notations; for example, 7000=7×10³ and 3750=3×10³+7×10²+5×10¹
A13: AC9M7N04 | B13: 7 | C13: Number | D13: find equivalent representations of rational numbers and represent rational numbers on a number line | E13: 1 | F13: investigating equivalence of fractions using common multiples and a fraction wall, diagrams or a number line to show that a fraction such as 2/3 is equivalent to 4/6 and 6/9 and therefore 2/3 < 5/6
... A403: AC9M10P02 | B403: 10 | C403: Probability | D403: design and conduct repeated chance experiments and simulations using digital tools to model conditional probability and interpret results | E403: 5 | F403: using simulation to predict the number of people likely to be infected with a strain of flu or virus

Sheet SA Mapping
A1: SA Year | B1: Strand | C1: SA Conceptual Understanding | D1: AC9 Descriptor(s) attached | E1: SA adaptation flag
A2: (populate from SA Curriculum Prototype PDF)
A4: Notes:
A5: • * after code = SA adaptation of AC9 descriptor
A6: • ^ after code = SA-created descriptor not in AC9
A7: • Some AC9 descriptors sit under different SA Year than ACARA Year (e.g. AC9M8X may be SA Year 7).

Sheet Coverage Report
A1: Coverage Report
A3: Status summary
A4: Total lessons planned | B4: =COUNTA(Lessons!A2:A1000)
A5: Planned | B5: =COUNTIF(Lessons!N2:N1000,"Planned")
A6: Drafted | B6: =COUNTIF(Lessons!N2:N1000,"Drafted")
A7: Generated | B7: =COUNTIF(Lessons!N2:N1000,"Generated")
A8: Reviewed | B8: =COUNTIF(Lessons!N2:N1000,"Reviewed")
A9: Published | B9: =COUNTIF(Lessons!N2:N1000,"Published")
A12: Lessons planned by Year × Strand
A13: Year | B13: Number | C13: Algebra | D13: Measurement | E13: Space | F13: Statistics | G13: Probability | H13: Total
A14: 7 | B14: =COUNTIFS(Lessons!B:B,7,Lessons!C:C,"Number") | C14: =COUNTIFS(Lessons!B:B,7,Lessons!C:C,"Algebra") | D14: =COUNTIFS(Lessons!B:B,7,Lessons!C:C,"Measurement") | E14: =COUNTIFS(Lessons!B:B,7,Lessons!C:C,"Space") | F14: =COUNTIFS(Lessons!B:B,7,Lessons!C:C,"Statistics") | G14: =COUNTIFS(Lessons!B:B,7,Lessons!C:C,"Probability") | H14: =SUM(B14:G14)
A15: 8 | B15: =COUNTIFS(Lessons!B:B,8,Lessons!C:C,"Number") | C15: =COUNTIFS(Lessons!B:B,8,Lessons!C:C,"Algebra") | D15: =COUNTIFS(Lessons!B:B,8,Lessons!C:C,"Measurement") | E15: =COUNTIFS(Lessons!B:B,8,Lessons!C:C,"Space") | F15: =COUNTIFS(Lessons!B:B,8,Lessons!C:C,"Statistics") | G15: =COUNTIFS(Lessons!B:B,8,Lessons!C:C,"Probability") | H15: =SUM(B15:G15)
A16: 9 | B16: =COUNTIFS(Lessons!B:B,9,Lessons!C:C,"Number") | C16: =COUNTIFS(Lessons!B:B,9,Lessons!C:C,"Algebra") | D16: =COUNTIFS(Lessons!B:B,9,Lessons!C:C,"Measurement") | E16: =COUNTIFS(Lessons!B:B,9,Lessons!C:C,"Space") | F16: =COUNTIFS(Lessons!B:B,9,Lessons!C:C,"Statistics") | G16: =COUNTIFS(Lessons!B:B,9,Lessons!C:C,"Probability") | H16: =SUM(B16:G16)
A17: 10 | B17: =COUNTIFS(Lessons!B:B,10,Lessons!C:C,"Number") | C17: =COUNTIFS(Lessons!B:B,10,Lessons!C:C,"Algebra") | D17: =COUNTIFS(Lessons!B:B,10,Lessons!C:C,"Measurement") | E17: =COUNTIFS(Lessons!B:B,10,Lessons!C:C,"Space") | F17: =COUNTIFS(Lessons!B:B,10,Lessons!C:C,"Statistics") | G17: =COUNTIFS(Lessons!B:B,10,Lessons!C:C,"Probability") | H17: =SUM(B17:G17)
A18: Total | B18: =SUM(B14:B17) | C18: =SUM(C14:C17) | D18: =SUM(D14:D17) | E18: =SUM(E14:E17) | F18: =SUM(F14:F17) | G18: =SUM(G14:G17) | H18: =SUM(H14:H17)
A21: Descriptors not yet covered
A22: (See Descriptors sheet; this view to be added as a manual filter or pivot. Auto-coverage check is in the Notes section below.)
A25: How to use
A26: • Status summary (B4-B9) updates automatically as Lessons rows are updated.
A27: • Year × Strand grid shows where the library is dense vs sparse.
A28: • To find AC9 codes not yet covered: filter the Descriptors sheet by Code, then check if that code appears in Lessons column G.
A29: • When the library is mature, add a pivot table here for descriptor-level coverage.
